Workbook
Name UKHoliday: 'UK Holiday'!$A$1:$A$3

Sheet Attendance Dump
A1: Name | B1: Employee Code | C1: Role | D1: Function | E1: 46079 | F1: =E1+1 -> 46080 | G1: =F1+1 -> 46081 | H1: =G1+1 -> 46082 | I1: =H1+1 -> 46083 | J1: =I1+1 -> 46084 | K1: =J1+1 -> 46085 | L1: =K1+1 -> 46086 | M1: =L1+1 -> 46087 | ... AI1: =AH1+1 -> 46109
A2: A B Jassna | B2: BOI9592 | E2: P | F2: P | G2: P | H2: WO | I2: PL | J2: P | K2: P | L2: P | M2: P | N2: P | O2: WO | P2: P | Q2: P | R2: P | S2: P | T2: P | U2: P | V2: WO | W2: P | X2: P | Y2: P | Z2: H(P) | AA2: PL | AB2: PL | AC2: WO | AD2: P | AE2: P | AF2: P
A3: A Dhanasekaran | B3: BOI10140 | E3: P | F3: P | G3: P | H3: WO | I3: P | J3: P | K3: P | L3: P | M3: P | N3: P | O3: WO | P3: P | Q3: P | R3: P | S3: P | T3: P | U3: P | V3: WO | W3: P | X3: P | Y3: PL | Z3: H(P) | AA3: P | AB3: P | AC3: WO | AD3: P | AE3: P | AF3: P
A4: A Mary Anitha | B4: BOI10437 | E4: P | F4: P | G4: P | H4: WO | I4: P | J4: P | K4: P | L4: P | M4: P | N4: P | O4: WO | P4: P | Q4: P | R4: P | S4: P | T4: P | U4: P | V4: WO | W4: P | X4: P | Y4: P | Z4: H(P) | AA4: P | AB4: P | AC4: WO | AD4: P | AE4: P | AF4: P
A5: A Muthuramalingam | B5: BOI9884 | E5: P | F5: P | G5: P | H5: WO | I5: P | J5: P | K5: P | L5: PL | M5: PL | N5: P | O5: WO | P5: P | Q5: P | R5: P | S5: P | T5: P | U5: P | V5: WO | W5: P | X5: P | Y5: P | Z5: H(P) | AA5: P | AB5: P | AC5: WO | AD5: P | AE5: P | AF5: P
A6: A Ramesh | B6: BOI9862 | E6: PL-HL | F6: P | G6: P | H6: WO | I6: P | J6: P | K6: P | L6: P | M6: P | N6: P | O6: WO | P6: P | Q6: P | R6: P | S6: P | T6: P | U6: P | V6: WO | W6: P | X6: P | Y6: P | Z6: H(P) | AA6: P | AB6: P | AC6: WO | AD6: P | AE6: P | AF6: P
A7: A Roopa | B7: BOI10166 | E7: PL-HL | F7: P | G7: P | H7: WO | I7: PM | J7: P | K7: P | L7: PL | M7: P | N7: P | O7: WO | P7: P | Q7: P | R7: P | S7: P | T7: P | U7: P | V7: WO | W7: P | X7: P | Y7: P | Z7: H | AA7: SL | AB7: P | AC7: WO | AD7: P | AE7: P | AF7: P
A8: A Shalini R | B8: BOI10368 | E8: P | F8: P | G8: P | H8: WO | I8: P | J8: P | K8: P | L8: P | M8: P | N8: P | O8: WO | P8: P | Q8: P | R8: P | S8: P | T8: P | U8: P | V8: WO | W8: P | X8: P | Y8: P | Z8: H(P) | AA8: P | AB8: P | AC8: WO | AD8: P | AE8: P | AF8: P
A9: A Tanveer | B9: BOI8502 | E9: P | F9: P | G9: P | H9: WO | I9: P | J9: P | K9: P | L9: P | M9: P | N9: P | O9: WO | P9: P | Q9: P | R9: P | S9: P | T9: P | U9: P | V9: WO | W9: P | X9: P | Y9: P | Z9: H(P) | AA9: P | AB9: P | AC9: WO | AD9: PL | AE9: P | AF9: P
A10: Aasif Nabi Marazi | B10: BOI9101 | E10: P | F10: P | G10: P | H10: WO | I10: SL-HLA1 | J10: SL-HL | K10: P | L10: P | M10: P | N10: P | O10: WO | P10: P | Q10: P | R10: P | S10: P | T10: P | U10: P | V10: WO | W10: P | X10: P | Y10: P | Z10: H(P) | AA10: P | AB10: DL | AC10: WO | AD10: P | AE10: P | AF10: P
A11: Abdul Kalam | B11: BOI11072 | E11: P | F11: P | G11: P | H11: WO | I11: P | J11: P | K11: P | L11: P | M11: P | N11: P | O11: WO | P11: P | Q11: P | R11: P | S11: P | T11: P | U11: P | V11: WO | W11: P | X11: P | Y11: PL | Z11: H(P) | AA11: P | AB11: DL | AC11: WO | AD11: LWP-LWP | AE11: P | AF11: P
A12: Ambily P | B12: BOI10563 | E12: P | F12: P | G12: P | H12: WO | I12: P | J12: PL | K12: P | L12: P | M12: PL | N12: P | O12: WO | P12: P | Q12: P | R12: P | S12: P | T12: P | U12: P | V12: WO | W12: P | X12: P | Y12: SL-HL | Z12: H(P) | AA12: P | AB12: P | AC12: WO | AD12: P | AE12: P | AF12: P
A13: Ammeripadathu Bindu sundaresan | B13: BOI11040 | E13: P | F13: P | G13: BL | H13: WO | I13: P | J13: P | K13: P | L13: P | M13: P | N13: P | O13: WO | P13: P | Q13: P | R13: P | S13: P | T13: P | U13: P | V13: WO | W13: P | X13: P | Y13: P | Z13: H(P) | AA13: P | AB13: P | AC13: WO | AD13: P | AE13: P | AF13: P
... A23: Anoop Kumar Singh s | B23: BOI9952 | E23: P | F23: P | G23: PL | H23: WO | I23: P | J23: P | K23: P | L23: SL | M23: P | N23: PL | O23: WO | P23: P | Q23: P | R23: P | S23: P | T23: P | U23: PL | V23: WO | W23: P | X23: P | Y23: P | Z23: H(P) | AA23: P | AB23: P | AC23: WO | AD23: P | AE23: P | AF23: P
A24: Arjitha Devi J | B24: BOI11118 | E24: P | F24: P | G24: A | H24: WO | I24: P | J24: P | K24: P
A25: Arjun G M | B25: BOI8657 | E25: P | F25: P | G25: P | H25: WO | I25: P | J25: P | K25: P | L25: P | M25: P | N25: PL | O25: WO | P25: P | Q25: P | R25: P | S25: P | T25: P | U25: P | V25: WO | W25: PL | X25: P | Y25: P | Z25: H(P) | AA25: P | AB25: P | AC25: WO | AD25: P | AE25: P | AF25: P
A26: Arun J | B26: BOI8618 | E26: P | F26: P | G26: P | H26: WO | I26: SL | J26: P | K26: P | L26: P | M26: P | N26: PL | O26: WO | P26: P | Q26: P | R26: P | S26: P | T26: P | U26: P | V26: WO | W26: P | X26: P | Y26: P | Z26: H | AA26: P | AB26: P | AC26: WO | AD26: P | AE26: P | AF26: P
A27: Arunkumar T | B27: BOI10378 | E27: P | F27: P | G27: P | H27: WO | I27: PL | J27: P | K27: P | L27: P | M27: P | N27: P | O27: WO | P27: P | Q27: P | R27: P | S27: P | T27: P | U27: P | V27: WO | W27: P | X27: P | Y27: P | Z27: H(P) | AA27: P | AB27: P | AC27: WO | AD27: P | AE27: P | AF27: P
A28: Ashwini B S | B28: BOI8013 | E28: P | F28: P | G28: P | H28: WO | I28: P | J28: P | K28: P | L28: P | M28: P | N28: P | O28: WO | P28: P | Q28: P | R28: P | S28: P | T28: P | U28: P | V28: WO | W28: P | X28: P | Y28: P | Z28: H(P) | AA28: P | AB28: P | AC28: WO | AD28: P | AE28: P | AF28: P
A29: Ashwini Rao | B29: BOI10962 | E29: P | F29: P | G29: P | H29: WO | I29: P | J29: P | K29: P | L29: P | M29: P | N29: P | O29: WO | P29: P | Q29: P | R29: P | S29: P | T29: P | U29: P | V29: WO | W29: P | X29: P | Y29: P | Z29: H | AA29: P | AB29: P | AC29: WO | AD29: P | AE29: P | AF29: A
A30: Ayaz Ahmed Khan | B30: BOI9340 | E30: P | F30: P | G30: P | H30: WO | I30: P | J30: P | K30: P | L30: P | M30: P | N30: P | O30: WO | P30: P | Q30: P | R30: P | S30: P | T30: P | U30: P | V30: WO | W30: P | X30: P | Y30: P | Z30: H(P) | AA30: P | AB30: DL | AC30: WO | AD30: P | AE30: P | AF30: P
A31: Azeezulla Shariff N | B31: BOI10224 | E31: P | F31: P | G31: P | H31: WO | I31: P | J31: P | K31: P | L31: P | M31: P | N31: P | O31: WO | P31: P | Q31: P | R31: P | S31: P | T31: P | U31: P | V31: WO | W31: P | X31: P | Y31: P | Z31: H(P) | AA31: P | AB31: DL | AC31: WO | AD31: P | AE31: P | AF31: P
A32: B Deneshkumar | B32: BOI10126 | E32: A | F32: A | G32: A | H32: WO | I32: A | J32: A
A33: B P R prasad rao | B33: BOI8770 | E33: P | F33: P | G33: P | H33: WO | I33: P | J33: P | K33: P | L33: P | M33: P | N33: P | O33: WO | P33: P | Q33: P | R33: P | S33: P | T33: P | U33: P | V33: WO | W33: SL | X33: P | Y33: P | Z33: H | AA33: P | AB33: P | AC33: WO | AD33: P | AE33: P | AF33: P
A34: B S Varahi | B34: BOI10613 | E34: PL | F34: P | G34: P | H34: WO | I34: P | J34: P | K34: P | L34: P | M34: P | N34: P | O34: WO | P34: P | Q34: P | R34: P | S34: P | T34: P | U34: P | V34: WO | W34: P | X34: P | Y34: P | Z34: H | AA34: P | AB34: P | AC34: WO | AD34: P | AE34: SL | AF34: SL
A35: Badrudduja A | B35: BOI10517 | E35: P | F35: P | G35: P | H35: WO | I35: P | J35: P | K35: P | L35: P | M35: P | N35: P | O35: WO | P35: P | Q35: P | R35: P | S35: P | T35: P | U35: P | V35: WO | W35: P | X35: P | Y35: P | Z35: H(P) | AA35: PL | AB35: PL | AC35: WO | AD35: P | AE35: P | AF35: P
A36: Basavanni Laxman Tigadi | B36: BOI9978 | E36: P | F36: PL-HL | G36: P | H36: WO | I36: P | J36: P | K36: P | L36: P | M36: SL-HL | N36: P | O36: WO | P36: P | Q36: P | R36: PL-HL | S36: P | T36: P | U36: P | V36: WO | W36: P | X36: P | Y36: PL-HL | Z36: H | AA36: P | AB36: P | AC36: WO | AD36: P | AE36: P | AF36: P
A37: Bhagat Singh Narbahadur khatayat | B37: BOI10668 | E37: P | F37: P | G37: P | H37: WO | I37: P | J37: SL-HL | K37: P | L37: P | M37: P | N37: P | O37: WO | P37: P | Q37: P | R37: P | S37: P | T37: P | U37: P | V37: WO | W37: P | X37: P | Y37: P | Z37: H(P) | AA37: P | AB37: P | AC37: WO | AD37: P | AE37: P | AF37: P
A38: Bharti . | B38: BOI11120 | E38: SL | F38: P | G38: P | H38: WO | I38: P | J38: P | K38: P | L38: P | M38: P | N38: P | O38: WO | P38: P | Q38: P | R38: P | S38: P | T38: P | U38: P | V38: WO | W38: P | X38: P | Y38: P | Z38: H(P) | AA38: P | AB38: P | AC38: WO | AD38: P | AE38: P | AF38: P
A39: Bhaskar S | B39: BOI8268 | E39: P | F39: P | G39: P | H39: WO | I39: P | J39: P | K39: P | L39: P | M39: P | N39: P | O39: WO | P39: P | Q39: P | R39: P | S39: P | T39: P | U39: P | V39: WO | W39: P | X39: P | Y39: P | Z39: H(P) | AA39: P | AB39: P | AC39: WO | AD39: P | AE39: P | AF39: P
A40: Bhavani K | B40: BOI10977 | E40: P | F40: P | G40: P | H40: WO | I40: P | J40: P | K40: P | L40: P | M40: P | N40: P | O40: WO | P40: P | Q40: P | R40: P | S40: P | T40: P | U40: P | V40: WO | W40: P | X40: P | Y40: P | Z40: H(P) | AA40: P | AB40: P | AC40: WO | AD40: PL | AE40: CO | AF40: P
A41: Bhavya C | B41: BOI9253 | E41: P | F41: P | G41: PL | H41: WO | I41: P | J41: BL | K41: BL | L41: BL | M41: BL | N41: PL | O41: PL | P41: PL | Q41: PL | R41: P | S41: P | T41: P | U41: P | V41: WO | W41: P | X41: PL | Y41: PL | Z41: H | AA41: P | AB41: P | AC41: WO | AD41: P | AE41: P | AF41: P
A42: Bhoomika K | B42: BOI10587 | E42: P | F42: P | G42: P | H42: WO | I42: P | J42: P | K42: P | L42: P | M42: P | N42: P | O42: WO | P42: P | Q42: P | R42: P | S42: P | T42: P | U42: P | V42: WO | W42: P | X42: P | Y42: P | Z42: H(P) | AA42: P | AB42: P | AC42: WO | AD42: P | AE42: P | AF42: P
A43: Bhushan Shriprakash Kokal | B43: BOI10575 | E43: P | F43: P | G43: P | H43: WO | I43: P | J43: P | K43: P | L43: P | M43: P | N43: P | O43: WO | P43: P | Q43: P | R43: P | S43: P | T43: P | U43: P | V43: WO | W43: P | X43: P | Y43: P | Z43: H(P) | AA43: P | AB43: P | AC43: WO | AD43: P | AE43: P | AF43: P
A44: Biju T a | B44: BOI10809 | E44: P | F44: P | G44: P | H44: WO | I44: P | J44: P | K44: P | L44: P | M44: P | N44: P | O44: WO | P44: P | Q44: P | R44: P | S44: P | T44: P | U44: P | V44: WO | W44: P | X44: P | Y44: P | Z44: H | AA44: PL | AB44: P | AC44: WO | AD44: P | AE44: P | AF44: P
... A56: Clement Kiran | B56: BOI11038 | E56: P | F56: P | G56: P | H56: WO | I56: P | J56: P | K56: P | L56: P | M56: P | N56: P | O56: WO | P56: P | Q56: P | R56: P | S56: P | T56: P | U56: P | V56: WO | W56: P | X56: P | Y56: P | Z56: H(P) | AA56: P | AB56: P | AC56: WO | AD56: P | AE56: P | AF56: A
A57: Constantin Aseriea Jefferson | B57: BOI10058 | E57: P | F57: P | G57: A | H57: WO | I57: LWP-LWP | J57: LWP-LWP | K57: LWP-LWP | L57: LWP-LWP | M57: A
A58: D Rajkumar | B58: BOI9857 | E58: P | F58: P | G58: P | H58: WO | I58: P | J58: P | K58: P | L58: P | M58: P | N58: P | O58: WO | P58: P | Q58: P | R58: P | S58: P | T58: P | U58: P | V58: WO | W58: P | X58: P | Y58: P | Z58: H(P) | AA58: P | AB58: P | AC58: WO | AD58: P | AE58: P | AF58: BL
A59: Dakshayini D | B59: BOI11173 | E59: P | F59: P | G59: P | H59: WO | I59: P | J59: P | K59: P | L59: P | M59: P | N59: P | O59: WO | P59: P | Q59: P | R59: P | S59: P | T59: P | U59: P | V59: WO | W59: P | X59: PL-HL | Y59: P | Z59: H(P) | AA59: PL-HL | AB59: PM | AC59: WO | AD59: P | AE59: BL | AF59: P
A60: Deepak Karkada | B60: BOI10918 | E60: P | F60: P | G60: P | H60: WO | I60: P | J60: P | K60: P | L60: P | M60: P | N60: P | O60: WO | P60: PL | Q60: P | R60: P | S60: P | T60: P | U60: P | V60: WO | W60: SL | X60: P | Y60: P | Z60: H(P) | AA60: P | AB60: P | AC60: WO | AD60: P | AE60: PL-HL | AF60: PL-HL
...

Sheet Productivity Dump
E1: {=IF(E3<TODAY(),IF(WEEKDAY(E3, 2)=7, 0, IF(OR(WEEKDAY(E3, 2)={2,6}), 0.5, 1)),"")} -> 1 | F1: {=IF(F3<TODAY(),IF(WEEKDAY(F3, 2)=7, 0, IF(OR(WEEKDAY(F3, 2)={2,6}), 0.5, 1)),"")} -> 1 | G1: {=IF(G3<TODAY(),IF(WEEKDAY(G3, 2)=7, 0, IF(OR(WEEKDAY(G3, 2)={2,6}), 0.5, 1)),"")} -> 0.5 | H1: {=IF(H3<TODAY(),IF(WEEKDAY(H3, 2)=7, 0, IF(OR(WEEKDAY(H3, 2)={2,6}), 0.5, 1)),"")} -> 0 | I1: {=IF(I3<TODAY(),IF(WEEKDAY(I3, 2)=7, 0, IF(OR(WEEKDAY(I3, 2)={2,6}), 0.5, 1)),"")} -> 1 | J1: {=IF(J3<TODAY(),IF(WEEKDAY(J3, 2)=7, 0, IF(OR(WEEKDAY(J3, 2)={2,6}), 0.5, 1)),"")} -> 0.5 | K1: {=IF(K3<TODAY(),IF(WEEKDAY(K3, 2)=7, 0, IF(OR(WEEKDAY(K3, 2)={2,6}), 0.5, 1)),"")} -> 1 | L1: {=IF(L3<TODAY(),IF(WEEKDAY(L3, 2)=7, 0, IF(OR(WEEKDAY(L3, 2)={2,6}), 0.5, 1)),"")} -> 1 | ... AI1: {=IF(AI3<TODAY(),IF(WEEKDAY(AI3, 2)=7, 0, IF(OR(WEEKDAY(AI3, 2)={2,6}), 0.5, 1)),"")} -> 0.5
E2: =TEXT(E3,"ddd") -> Thu | F2: =TEXT(F3,"ddd") -> Fri | G2: =TEXT(G3,"ddd") -> Sat | H2: =TEXT(H3,"ddd") -> Sun | I2: =TEXT(I3,"ddd") -> Mon | J2: =TEXT(J3,"ddd") -> Tue | K2: =TEXT(K3,"ddd") -> Wed | L2: =TEXT(L3,"ddd") -> Thu | ... AI2: =TEXT(AI3,"ddd") -> Sat
A3: Emp Code | B3: Employee | C3: DIT ID | D3: TM | E3: 46079 | F3: =E3+1 -> 46080 | G3: =F3+1 -> 46081 | H3: =G3+1 -> 46082 | I3: =H3+1 -> 46083 | J3: =I3+1 -> 46084 | K3: =J3+1 -> 46085 | L3: =K3+1 -> 46086 | M3: =L3+1 -> 46087 | ... AI3: =AH3+1 -> 46109
A4: BOI9592 | B4: A B Jassna | C4: Jass9592 | D4: Anil | E4: 1002.266 | F4: 1083.322 | G4: 682.688 | H4: 0 | I4: 0 | J4: 1033.063 | K4: 1084.62 | L4: 1056.265 | M4: 1008.021 | N4: 1099.244 | O4: 0 | P4: 340.165 | Q4: 1012.033 | R4: 1043.388 | S4: 1001.252 | T4: 1022.374 | U4: 762.132 | V4: 516.012 | W4: 628.474 | X4: 1018.569 | Y4: 1091.693 | Z4: 1053.077 | AA4: 0 | AB4: 0 | AC4: 0 | AD4: 604.056 | AE4: 1011.389 | AF4: 1003.818
A5: BOI10140 | B5: A Dhanasekaran | C5: Dhan10140 | D5: Ranjith M | E5: 1038.172 | F5: 1105.252 | G5: 922.727 | H5: 0 | I5: 510.128 | J5: 1105.897 | K5: 1119.359 | L5: 1102.799 | M5: 1119.721 | N5: 986.032 | O5: 0 | P5: 546.739 | Q5: 1081.437 | R5: 1051.541 | S5: 1064.514 | T5: 1012.09 | U5: 711.031 | V5: 0 | W5: 538.4 | X5: 972.236 | Y5: 0 | Z5: 1109.603 | AA5: 1007.542 | AB5: 393.383 | AC5: 0 | AD5: 525.417 | AE5: 1040.972 | AF5: 955.173
A6: BOI10437 | B6: A Mary Anitha | C6: Mary10437 | D6: Sunil Kumar K | E6: 953.101 | F6: 566.981 | G6: 510.856 | H6: 0 | I6: 629.809 | J6: 1067.396 | K6: 1006.794 | L6: 1055.885 | M6: 1123.748 | N6: 356.517 | O6: 0 | P6: 718.776 | Q6: 1038.757 | R6: 1103.469 | S6: 1050.086 | T6: 1059.459 | U6: 710.949 | V6: 0 | W6: 468.687 | X6: 1063.563 | Y6: 1119.962 | Z6: 1006.474 | AA6: 1021.64 | AB6: 432.764 | AC6: 0 | AD6: 614.501 | AE6: 1020.527 | AF6: 783.349
A7: BOI9884 | B7: A Muthuramalingam | C7: Muth9884 | D7: Prashanth | E7: 863.454 | F7: 816.43 | G7: 544.081 | H7: 0 | I7: 405.846 | J7: 822.399 | K7: 881.457 | L7: 0 | M7: 0 | N7: 290.448 | O7: 0 | P7: 417.158 | Q7: 980.771 | R7: 919.082 | S7: 878.82 | T7: 1013.105 | U7: 468.831 | V7: 230.789 | W7: 481.545 | X7: 1091.399 | Y7: 1002.839 | Z7: 1027.538 | AA7: 933.252 | AB7: 90.879 | AC7: 210.187 | AD7: 523.103 | AE7: 910.727 | AF7: 929.224
A8: BOI9862 | B8: A Ramesh | C8: Rame9862 | D8: Hiren Patel | E8: 819.979 | F8: 1759.535 | G8: 1533.636 | H8: 9.169 | I8: 1938.686 | J8: 1726.051 | K8: 1983.239 | L8: 1389.842 | M8: 1719.133 | N8: 1323.477 | O8: 0 | P8: 1716.221 | Q8: 1714.014 | R8: 1739.605 | S8: 1663.632 | T8: 1651.428 | U8: 1335.555 | V8: 0 | W8: 1571.648 | X8: 1669.813 | Y8: 1673.443 | Z8: 1755.835 | AA8: 1346.876 | AB8: 1084.405 | AC8: 0 | AD8: 1502.545 | AE8: 1863.982 | AF8: 1729.441
A9: BOI10166 | B9: A Roopa | C9: Roop10166 | D9: Anil | E9: 262.522 | F9: 1021.225 | G9: 597.767 | H9: 0 | I9: 101.168 | J9: 1072.168 | K9: 1010.816 | L9: 0 | M9: 1230.243 | N9: 969.197 | O9: 0 | P9: 456.738 | Q9: 1042.396 | R9: 1018.923 | S9: 1016.731 | T9: 1026.641 | U9: 500.799 | V9: 0 | W9: 463.231 | X9: 1000 | Y9: 716.087 | Z9: 213.03 | AA9: 181.246 | AB9: 457.187 | AC9: 0 | AD9: 434.259 | AE9: 817.139 | AF9: 752.799
A10: BOI8502 | B10: A Tanveer | C10: Tanv8502 | D10: Sunil Kumar K | E10: 1594.801 | F10: 1646.131 | G10: 1513.491 | H10: 0 | I10: 1074.904 | J10: 1574.191 | K10: 1546.987 | L10: 1638.198 | M10: 1578.078 | N10: 1572.937 | O10: 0 | P10: 1518.076 | Q10: 1566.419 | R10: 1578.248 | S10: 1538.947 | T10: 1530.912 | U10: 1553.997 | V10: 0 | W10: 986.153 | X10: 1533.319 | Y10: 1603.556 | Z10: 1572.138 | AA10: 1542.301 | AB10: 581.124 | AC10: 0 | AD10: 0 | AE10: 1545.075 | AF10: 1528.672
A11: BOI10368 | B11: A shalini R | C11: Asha10368 | D11: Prashanth | E11: 909.141 | F11: 991.221 | G11: 340.049 | H11: 0 | I11: 461.99 | J11: 984.546 | K11: 1006.416 | L11: 955.801 | M11: 1175.561 | N11: 436.741 | O11: 0 | P11: 469.958 | Q11: 975.714 | R11: 1015.978 | S11: 1010.819 | T11: 944.618 | U11: 503.277 | V11: 0 | W11: 529.646 | X11: 1234.666 | Y11: 1003.295 | Z11: 1013.175 | AA11: 685.728 | AB11: 509.6 | AC11: 0 | AD11: 568.22 | AE11: 953.482 | AF11: 1020.991
A12: BOI9101 | B12: Aasif Nabi Marazi | C12: Mara9101 | D12: Anil | E12: 1076.625 | F12: 1583.148 | G12: 1214.228 | H12: 0 | I12: 0 | J12: 410.152 | K12: 1520.736 | L12: 1506.84 | M12: 1127.906 | N12: 1007.305 | O12: 296.107 | P12: 570.568 | Q12: 1549.781 | R12: 1510.487 | S12: 1318.393 | T12: 1451.402 | U12: 756.014 | V12: 828.955 | W12: 921.29 | X12: 1043.429 | Y12: 1435.918 | Z12: 1177.67 | AA12: 807.459 | AB12: 347.721 | AC12: 445.812 | AD12: 837.383 | AE12: 1146.411 | AF12: 1269.089
A13: BOI10563 | B13: Ambily P | C13: Ambi10563 | D13: Sunil Kumar K | E13: 952.279 | F13: 969.521 | G13: 444.058 | H13: 0 | I13: 458.354 | J13: 0 | K13: 977.197 | L13: 969.17 | M13: 0 | N13: 724.147 | O13: 0 | P13: 518.103 | Q13: 975.536 | R13: 965.458 | S13: 918.028 | T13: 976.305 | U13: 548.105 | V13: 0 | W13: 467.693 | X13: 963.595 | Y13: 551.109 | Z13: 1003.008 | AA13: 998.696 | AB13: 29.615 | AC13: 0 | AD13: 426.354 | AE13: 722.578 | AF13: 1047.674
A14: BOI10691 | B14: Amraj C M | C14: Amra10691 | D14: Anil | E14: 1669.321 | F14: 1198.073 | G14: 1065.518 | H14: 0 | I14: 322.061 | J14: 1201.119 | K14: 1155.239 | L14: 1289.554 | M14: 1367.576 | N14: 834.334 | O14: 0 | P14: 470.303 | Q14: 1466.493 | R14: 0 | S14: 1410.118 | T14: 1582.851 | U14: 975.546 | V14: 172.322 | W14: 676.97 | X14: 1618.37 | Y14: 1269.286 | Z14: 1518.98 | AA14: 1588.019 | AB14: 824.536 | AC14: 134.214 | AD14: 503.783 | AE14: 1146.625 | AF14: 1216.271
A15: BOI10992 | B15: Amrita Ramaning Gundap | C15: Amri10992 | D15: Anil | E15: 812.046 | F15: 925.2 | G15: 637.013 | H15: 0 | I15: 197.416 | J15: 988.895 | K15: 895.756 | L15: 916.185 | M15: 1047.016 | N15: 638.072 | O15: 0 | P15: 434.044 | Q15: 907.167 | R15: 994.025 | S15: 798.848 | T15: 1039.23 | U15: 400.526 | V15: 0 | W15: 446.585 | X15: 751.449 | Y15: 757.11 | Z15: 719.757 | AA15: 842.324 | AB15: 315.029 | AC15: 381.889 | AD15: 486.418 | AE15: 1085.414 | AF15: 1206.095
... A300: BOI11191 | B300: Reena R | C300: Reen11191 | D300: Prashanth | E300: 568.389 | F300: 543.157 | G300: 181.772 | H300: 0 | I300: 425.788 | J300: 575.292 | K300: 509.895 | L300: 508.311 | M300: 540.463 | N300: 499.984 | O300: 0 | P300: 123.571 | Q300: 290.632 | R300: 518.928 | S300: 503.678 | T300: 917.157 | U300: 1026.114 | V300: 0 | W300: 391.143 | X300: 908.142 | Y300: 943.694 | Z300: 919.943 | AA300: 452.205 | AB300: 150.785 | AC300: 0 | AD300: 250.247 | AE300: 905.552 | AF300: 604.083
A301: BOI11194 | B301: Uttam Kumar Roy | C301: utta11194 | D301: Ranjith M | L301: 44.276 | M301: 235.183 | N301: 0 | O301: 0 | P301: 33.492 | Q301: 265.756 | R301: 482.07 | S301: 505.995 | T301: 366.769 | U301: 234.046 | V301: 0 | W301: 125.569 | X301: 523.107 | Y301: 282.677 | Z301: 307.137 | AA301: 304.229 | AB301: 144.353 | AC301: 0 | AD301: 98.815 | AE301: 494.859 | AF301: 600.441

Sheet Active Hour's Dump
D1: =TEXT(D2,"ddd") -> Thu | E1: =TEXT(E2,"ddd") -> Fri | F1: =TEXT(F2,"ddd") -> Sat | G1: =TEXT(G2,"ddd") -> Sun | H1: =TEXT(H2,"ddd") -> Mon | I1: =TEXT(I2,"ddd") -> Tue | J1: =TEXT(J2,"ddd") -> Wed | K1: =TEXT(K2,"ddd") -> Thu | ... AH1: =TEXT(AH2,"ddd") -> Sat
A2: DUP Name | B2: TL Name | C2: PM Name | D2: 46079 | E2: =D2+1 -> 46080 | F2: =E2+1 -> 46081 | G2: =F2+1 -> 46082 | H2: =G2+1 -> 46083 | I2: =H2+1 -> 46084 | J2: =I2+1 -> 46085 | K2: =J2+1 -> 46086 | L2: =K2+1 -> 46087 | ... AH2: =AG2+1 -> 46109 | AI2: Average
A3: Amul10910 | B3: Hiren Patel | D3: 15.25 | E3: 12.333333 | F3: 8.1666667 | H3: 9.75 | I3: 0.66666667 | J3: 12.416667 | K3: 14.166667 | L3: 12 | M3: 7.4166667 | N3: 0.083333333 | O3: 11.166667 | P3: 12.583333 | Q3: 12.333333 | R3: 11.416667 | S3: 8.5833333 | T3: 9.4166667 | V3: 9.8333333 | W3: 10.583333 | X3: 13.083333 | Y3: 0.66666667 | Z3: 13.333333 | AA3: 8.0833333 | AC3: 9.5 | AD3: 12.25 | AE3: 11.916667 | AI3: =IFERROR(AVERAGEIFS(D3:AH3,$D$1:$AH$1,"<>Sun",$D$1:$AH$1,"<>Sat",$D$1:$AH$1,"<>Mon"),"") -> 10.848958
A4: Anat11003 | B4: Hiren Patel | D4: 6.3333333 | E4: 6.75 | F4: 4.5833333 | H4: 5.6666667 | I4: 5.75 | K4: 6.5 | L4: 6.25 | M4: 5.75 | O4: 6.9166667 | P4: 5.9166667 | Q4: 6.25 | R4: 6.75 | S4: 5.8333333 | T4: 5.3333333 | V4: 5.8333333 | W4: 6.25 | X4: 6.4166667 | Y4: 6.9166667 | Z4: 6.4166667 | AA4: 2.75 | AC4: 5.5833333 | AE4: 6.5833333 | AI4: =IFERROR(AVERAGEIFS(D4:AH4,$D$1:$AH$1,"<>Sun",$D$1:$AH$1,"<>Sat",$D$1:$AH$1,"<>Mon"),"") -> 6.3511905
A5: Anoo9952 | B5: Hiren Patel | D5: 11.5 | E5: 11.333333 | H5: 6.5833333 | I5: 12.25 | J5: 10.916667 | K5: 0.083333333 | L5: 11.416667 | M5: 5.3333333 | O5: 5.8333333 | P5: 11.25 | Q5: 10.916667 | R5: 11.75 | S5: 9.9166667 | T5: 3.5 | V5: 6 | W5: 10.916667 | X5: 11.083333 | Y5: 11.5 | Z5: 11.083333 | AA5: 3.3333333 | AC5: 7.1666667 | AD5: 8.6666667 | AE5: 12.333333 | AI5: =IFERROR(AVERAGEIFS(D5:AH5,$D$1:$AH$1,"<>Sun",$D$1:$AH$1,"<>Sat",$D$1:$AH$1,"<>Mon"),"") -> 10.432292
A6: Bhas8268 | B6: Hiren Patel | D6: 10.75 | E6: 10.25 | F6: 6.75 | G6: 2.6666667 | H6: 4.25 | I6: 9.0833333 | J6: 10.416667 | K6: 11 | L6: 10.416667 | M6: 9.8333333 | N6: 2.3333333 | O6: 5.5 | P6: 9.5 | Q6: 10.416667 | R6: 10 | S6: 10.25 | T6: 7.6666667 | U6: 4.3333333 | V6: 8.25 | W6: 9.8333333 | X6: 10.333333 | Y6: 12.5 | Z6: 11.75 | AA6: 5.5 | AB6: 3.5833333 | AC6: 8.0833333 | AD6: 10.5 | AE6: 9.9166667 | AI6: =IFERROR(AVERAGEIFS(D6:AH6,$D$1:$AH$1,"<>Sun",$D$1:$AH$1,"<>Sat",$D$1:$AH$1,"<>Mon"),"") -> 10.432292
A7: Bhav10977 | B7: Hiren Patel | D7: 6.9166667 | E7: 7.0833333 | F7: 3.75 | H7: 4.1666667 | I7: 7.1666667 | J7: 6.9166667 | K7: 6.5 | L7: 6.25 | M7: 5.9166667 | O7: 5.1666667 | P7: 7.5833333 | Q7: 7.0833333 | R7: 8.0833333 | S7: 6.9166667 | T7: 5.0833333 | V7: 3.5833333 | W7: 7.8333333 | X7: 6.1666667 | Y7: 7.0833333 | Z7: 6.1666667 | AA7: 3.5 | AD7: 0.41666667 | AE7: 7.4166667 | AI7: =IFERROR(AVERAGEIFS(D7:AH7,$D$1:$AH$1,"<>Sun",$D$1:$AH$1,"<>Sat",$D$1:$AH$1,"<>Mon"),"") -> 6.5989583
A8: Biju10809 | B8: Hiren Patel | D8: 8.25 | E8: 7.5 | F8: 4.4166667 | H8: 5.0833333 | I8: 6.4166667 | J8: 6.6666667 | K8: 7.5833333 | L8: 7 | M8: 6.5 | O8: 5.75 | P8: 6.8333333 | Q8: 5.8333333 | R8: 7 | S8: 6.9166667 | T8: 3.5 | V8: 7 | W8: 6.3333333 | X8: 6.75 | AA8: 2.25 | AC8: 5.75 | AD8: 5.9166667 | AE8: 7.5 | AI8: =IFERROR(AVERAGEIFS(D8:AH8,$D$1:$AH$1,"<>Sun",$D$1:$AH$1,"<>Sat",$D$1:$AH$1,"<>Mon"),"") -> 6.8928571
A9: Vish10337 | B9: Hiren Patel | D9: 8.8333333 | E9: 9.9166667 | F9: 7.25 | G9: 1 | H9: 5.3333333 | I9: 10.583333 | J9: 9.3333333 | K9: 10.166667 | L9: 9.3333333 | M9: 10.5 | N9: 0 | O9: 6 | P9: 10.583333 | Q9: 9.8333333 | R9: 10.333333 | S9: 9.1666667 | T9: 5.8333333 | V9: 5.9166667 | X9: 8.5 | Z9: 11.25 | AA9: 8.1666667 | AB9: 2.75 | AC9: 5.25 | AD9: 9.8333333 | AE9: 9.9166667 | AI9: =IFERROR(AVERAGEIFS(D9:AH9,$D$1:$AH$1,"<>Sun",$D$1:$AH$1,"<>Sat",$D$1:$AH$1,"<>Mon"),"") -> 9.827381
A10: Chan10524 | B10: Hiren Patel | D10: 7.3333333 | E10: 6.5 | F10: 5.4166667 | H10: 4.1666667 | I10: 6.1666667 | J10: 4.5833333 | K10: 6.0833333 | L10: 7.75 | M10: 5.9166667 | O10: 4.75 | P10: 7.0833333 | Q10: 6.4166667 | R10: 7.4166667 | S10: 7 | T10: 2.5 | V10: 3.1666667 | W10: 4.5 | X10: 6 | Y10: 4 | Z10: 3.6666667 | AA10: 2.6666667 | AC10: 3.5833333 | AD10: 4.6666667 | AE10: 5.75 | AI10: =IFERROR(AVERAGEIFS(D10:AH10,$D$1:$AH$1,"<>Sun",$D$1:$AH$1,"<>Sat",$D$1:$AH$1,"<>Mon"),"") -> 5.9322917
A11: Dhan8922 | B11: Hiren Patel | D11: 12.25 | E11: 11.833333 | F11: 0 | H11: 6.5 | I11: 11.416667 | J11: 11.166667 | K11: 11.083333 | L11: 10.75 | M11: 12.083333 | O11: 8.3333333 | P11: 10.75 | Q11: 11.833333 | R11: 11.333333 | S11: 11.083333 | T11: 5.5 | U11: 0 | V11: 9.5833333 | W11: 11.166667 | X11: 11.416667 | Y11: 8 | Z11: 6.5 | AA11: 7.6666667 | AC11: 8.6666667 | AD11: 10.666667 | AE11: 11.083333 | AI11: =IFERROR(AVERAGEIFS(D11:AH11,$D$1:$AH$1,"<>Sun",$D$1:$AH$1,"<>Sat",$D$1:$AH$1,"<>Mon"),"") -> 10.770833
A12: Faiz8263 | B12: Hiren Patel | D12: 12.833333 | E12: 10.416667 | F12: 7.9166667 | G12: 3.75 | H12: 7.8333333 | I12: 9.3333333 | J12: 8.0833333 | K12: 9.8333333 | L12: 9.25 | M12: 9.4166667 | N12: 4.75 | O12: 6.4166667 | P12: 12.083333 | Q12: 8.4166667 | R12: 11.666667 | S12: 8.5833333 | T12: 4.4166667 | U12: 5.5833333 | V12: 5.9166667 | W12: 3 | X12: 8.6666667 | Y12: 9.8333333 | Z12: 9.0833333 | AC12: 4.9166667 | AD12: 8.5 | AE12: 9 | AI12: =IFERROR(AVERAGEIFS(D12:AH12,$D$1:$AH$1,"<>Sun",$D$1:$AH$1,"<>Sat",$D$1:$AH$1,"<>Mon"),"") -> 9.2864583
A13: Gour10612 | B13: Hiren Patel | D13: 11 | E13: 10.166667 | F13: 5.1666667 | H13: 6.6666667 | I13: 9.5833333 | J13: 8.6666667 | K13: 10.166667 | L13: 10.5 | M13: 7.0833333 | N13: 0 | P13: 10.75 | Q13: 11.166667 | R13: 9.9166667 | S13: 9.4166667 | T13: 8.0833333 | V13: 9.9166667 | W13: 10.583333 | X13: 10.333333 | Y13: 8 | Z13: 11.166667 | AA13: 10.833333 | AC13: 6.75 | AD13: 7.3333333 | AE13: 7.4166667 | AI13: =IFERROR(AVERAGEIFS(D13:AH13,$D$1:$AH$1,"<>Sun",$D$1:$AH$1,"<>Sat",$D$1:$AH$1,"<>Mon"),"") -> 9.7604167
A14: Jeya9953 | B14: Hiren Patel | D14: 6.5 | E14: 7.75 | F14: 2.6666667 | H14: 2.5833333 | I14: 3.4166667 | J14: 7 | K14: 5.75 | L14: 7 | M14: 6.0833333 | O14: 2.8333333 | P14: 6.75 | Q14: 6.1666667 | R14: 7 | S14: 6.25 | T14: 3.4166667 | V14: 4.1666667 | W14: 8.25 | X14: 7.5833333 | Y14: 7.6666667 | Z14: 6.5 | AA14: 5.6666667 | AB14: 6.1666667 | AC14: 3.4166667 | AD14: 10.25 | AE14: 13.5 | AI14: =IFERROR(AVERAGEIFS(D14:AH14,$D$1:$AH$1,"<>Sun",$D$1:$AH$1,"<>Sat",$D$1:$AH$1,"<>Mon"),"") -> 7.3333333
A15: Poov10426 | B15: Hiren Patel | E15: 3.9166667 | F15: 2.8333333 | H15: 2 | I15: 4.1666667 | J15: 5.75 | K15: 6.6666667 | L15: 5.6666667 | M15: 4.9166667 | O15: 3.1666667 | P15: 5.8333333 | Q15: 6.6666667 | R15: 5.9166667 | S15: 7.6666667 | T15: 3.75 | V15: 2.5833333 | W15: 6.5 | X15: 5.9166667 | Y15: 3.3333333 | Z15: 4.8333333 | AA15: 2.5833333 | AC15: 2.8333333 | AD15: 5.75 | AE15: 8.4166667 | AI15: =IFERROR(AVERAGEIFS(D15:AH15,$D$1:$AH$1,"<>Sun",$D$1:$AH$1,"<>Sat",$D$1:$AH$1,"<>Mon"),"") -> 5.8
A16: Prav10468 | B16: Hiren Patel | D16: 10.166667 | E16: 9.75 | F16: 7.5833333 | G16: 1.6666667 | H16: 7.25 | I16: 7.6666667 | J16: 11 | K16: 10.333333 | L16: 10.166667 | M16: 10.583333 | N16: 1.5833333 | O16: 7.3333333 | P16: 12.25 | Q16: 10 | R16: 10.833333 | S16: 11 | T16: 8.3333333 | U16: 0.91666667 | V16: 8.8333333 | W16: 9.8333333 | X16: 10.75 | Y16: 9.5 | Z16: 9.75 | AA16: 7.6666667 | AB16: 2 | AC16: 8.6666667 | AD16: 10.333333 | AE16: 10.583333 | AI16: =IFERROR(AVERAGEIFS(D16:AH16,$D$1:$AH$1,"<>Sun",$D$1:$AH$1,"<>Sat",$D$1:$AH$1,"<>Mon"),"") -> 10.244792
A17: Sham9382 | B17: Hiren Patel | D17: 10.75 | E17: 11.666667 | F17: 7.3333333 | H17: 7.1666667 | I17: 11.25 | K17: 11 | L17: 12.5 | M17: 7.5833333 | O17: 7.8333333 | P17: 11.416667 | Q17: 11.416667 | R17: 12 | S17: 10.333333 | T17: 4.5833333 | V17: 7.8333333 | W17: 11.333333 | X17: 10.5 | Y17: 10.583333 | Z17: 10.25 | AA17: 3.0833333 | AC17: 6.25 | AD17: 10.416667 | AE17: 10.916667 | AI17: =IFERROR(AVERAGEIFS(D17:AH17,$D$1:$AH$1,"<>Sun",$D$1:$AH$1,"<>Sat",$D$1:$AH$1,"<>Mon"),"") -> 11.088889
A18: Mang10397 | B18: Hiren Patel | D18: 7.0833333 | E18: 10.083333 | F18: 1.9166667 | H18: 7.0833333 | I18: 10.416667 | J18: 9.25 | K18: 10 | L18: 9.6666667 | M18: 3.5 | O18: 8.3333333 | P18: 10 | Q18: 9.75 | R18: 10.083333 | S18: 8 | T18: 3.5 | V18: 4.8333333 | W18: 9.8333333 | X18: 10 | Y18: 9.1666667 | Z18: 7.25 | AA18: 6 | AB18: 0 | AC18: 7.5833333 | AD18: 9.8333333 | AE18: 7.9166667 | AI18: =IFERROR(AVERAGEIFS(D18:AH18,$D$1:$AH$1,"<>Sun",$D$1:$AH$1,"<>Sat",$D$1:$AH$1,"<>Mon"),"") -> 9.2708333
A19: Mari10549 | B19: Hiren Patel | D19: 9.3333333 | E19: 8.5 | F19: 7.0833333 | G19: 0.33333333 | H19: 7.8333333 | I19: 7.4166667 | J19: 8.6666667 | K19: 8.5833333 | L19: 8.25 | M19: 9.5833333 | O19: 6.75 | Q19: 10.333333 | R19: 10 | S19: 9.5 | V19: 7.25 | W19: 9.1666667 | X19: 9.1666667 | Y19: 6 | Z19: 6.9166667 | AA19: 6.5 | AC19: 6.5 | AD19: 8.75 | AE19: 7.25 | AI19: =IFERROR(AVERAGEIFS(D19:AH19,$D$1:$AH$1,"<>Sun",$D$1:$AH$1,"<>Sat",$D$1:$AH$1,"<>Mon"),"") -> 8.5222222
A20: Naze9128 | B20: Hiren Patel | D20: 5.4166667 | E20: 6.5833333 | F20: 4.1666667 | H20: 3.25 | I20: 7.25 | J20: 5.4166667 | K20: 6.75 | L20: 5.3333333 | M20: 5.3333333 | O20: 4.9166667 | P20: 7.5833333 | Q20: 6.9166667 | R20: 7.4166667 | S20: 5.6666667 | T20: 3.8333333 | V20: 4.5 | W20: 6.6666667 | X20: 7.25 | Y20: 4.5833333 | Z20: 5.3333333 | AA20: 0 | AI20: =IFERROR(AVERAGEIFS(D20:AH20,$D$1:$AH$1,"<>Sun",$D$1:$AH$1,"<>Sat",$D$1:$AH$1,"<>Mon"),"") -> 6.297619
A21: Nilo9960 | B21: Hiren Patel | D21: 5.9166667 | E21: 5.5833333 | F21: 2.75 | H21: 3.5833333 | I21: 5.6666667 | J21: 4.8333333 | K21: 5.5 | L21: 5.4166667 | M21: 4.8333333 | O21: 3.0833333 | P21: 5.5 | Q21: 5.6666667 | R21: 5.6666667 | S21: 5.5833333 | T21: 3.25 | V21: 1.3333333 | W21: 5 | X21: 6.4166667 | Y21: 4.3333333 | Z21: 5.8333333 | AA21: 2 | AC21: 1.8333333 | AD21: 3.9166667 | AE21: 6.9166667 | AI21: =IFERROR(AVERAGEIFS(D21:AH21,$D$1:$AH$1,"<>Sun",$D$1:$AH$1,"<>Sat",$D$1:$AH$1,"<>Mon"),"") -> 5.484375
A22: Nuth10677 | B22: Hiren Patel | D22: 8.9166667 | E22: 7.6666667 | F22: 4.75 | H22: 5.0833333 | I22: 8.8333333 | J22: 8.9166667 | K22: 8.5 | L22: 6.75 | M22: 7.25 | O22: 5.75 | P22: 8.75 | Q22: 6.9166667 | R22: 8 | S22: 8.5833333 | T22: 4.9166667 | V22: 3.75 | W22: 5.3333333 | X22: 7.3333333 | Y22: 5.8333333 | Z22: 7.1666667 | AA22: 1.75 | AC22: 2.5833333 | AD22: 5.6666667 | AE22: 5.9166667 | AI22: =IFERROR(AVERAGEIFS(D22:AH22,$D$1:$AH$1,"<>Sun",$D$1:$AH$1,"<>Sat",$D$1:$AH$1,"<>Mon"),"") -> 7.4427083
A23: Pras11050 | B23: Hiren Patel | O23: 3.8333333 | P23: 4.25 | Q23: 4.5833333 | R23: 4.4166667 | S23: 4.0833333 | T23: 2.5833333 | V23: 4.3333333 | W23: 1.5833333 | X23: 3.6666667 | Y23: 2.5833333 | Z23: 3.25 | AA23: 3.3333333 | AC23: 3.3333333 | AD23: 3.5833333 | AE23: 4 | AI23: =IFERROR(AVERAGEIFS(D23:AH23,$D$1:$AH$1,"<>Sun",$D$1:$AH$1,"<>Sat",$D$1:$AH$1,"<>Mon"),"") -> 3.6
A24: Priy9893 | B24: Hiren Patel | D24: 8.9166667 | E24: 8.6666667 | F24: 3.5 | H24: 5.4166667 | I24: 8.5 | J24: 2 | K24: 9.4166667 | L24: 9.3333333 | O24: 5 | P24: 8.8333333 | Q24: 8.75 | R24: 7.75 | S24: 8.3333333 | T24: 2.8333333 | V24: 3.8333333 | W24: 8.5 | X24: 9.6666667 | Y24: 8.6666667 | Z24: 8.9166667 | AA24: 4.6666667 | AC24: 5.5 | AD24: 9.75 | AE24: 9.25 | AI24: =IFERROR(AVERAGEIFS(D24:AH24,$D$1:$AH$1,"<>Sun",$D$1:$AH$1,"<>Sat",$D$1:$AH$1,"<>Mon"),"") -> 8.453125
A25: Deep10198 | B25: Hiren Patel | D25: 10.333333 | F25: 6.1666667 | H25: 7.5 | I25: 11.5 | J25: 10.25 | K25: 10.583333 | L25: 9.75 | M25: 8.3333333 | O25: 9 | P25: 10.416667 | Q25: 11.833333 | R25: 11.25 | S25: 10.166667 | T25: 4.25 | V25: 6.1666667 | W25: 10 | X25: 11.166667 | Y25: 12.166667 | Z25: 10.166667 | AA25: 2.6666667 | AC25: 5.5 | AE25: 9.9166667 | AI25: =IFERROR(AVERAGEIFS(D25:AH25,$D$1:$AH$1,"<>Sun",$D$1:$AH$1,"<>Sat",$D$1:$AH$1,"<>Mon"),"") -> 10.678571
A26: Rizw10031 | B26: Hiren Patel | D26: 6.25 | E26: 7.5833333 | F26: 5 | G26: 0.083333333 | H26: 4.8333333 | I26: 7.5 | J26: 6.6666667 | K26: 6.8333333 | L26: 6.25 | M26: 4.8333333 | N26: 0.083333333 | O26: 5.1666667 | P26: 7.6666667 | Q26: 6.9166667 | R26: 7.0833333 | S26: 7.5 | T26: 4.0833333 | U26: 0.33333333 | V26: 5.25 | W26: 7.0833333 | X26: 7.1666667 | Y26: 4.8333333 | Z26: 3.9166667 | AB26: 0.66666667 | AC26: 4.25 | AD26: 7.25 | AE26: 6.9166667 | AI26: =IFERROR(AVERAGEIFS(D26:AH26,$D$1:$AH$1,"<>Sun",$D$1:$AH$1,"<>Sat",$D$1:$AH$1,"<>Mon"),"") -> 6.7135417
A27: Salo9657 | B27: Hiren Patel | D27: 11.833333 | E27: 12 | F27: 5.0833333 | G27: 0.41666667 | H27: 7.5833333 | I27: 12.666667 | J27: 11.833333 | K27: 12 | L27: 12.916667 | O27: 8.5833333 | P27: 12.833333 | Q27: 10.583333 | R27: 11.75 | S27: 12.25 | T27: 8.1666667 | V27: 7.1666667 | W27: 9.4166667 | X27: 14.083333 | Y27: 11.333333 | Z27: 7.75 | AA27: 4 | AB27: 4.25 | AC27: 8.75 | AD27: 13.25 | AE27: 12.833333 | AI27: =IFERROR(AVERAGEIFS(D27:AH27,$D$1:$AH$1,"<>Sun",$D$1:$AH$1,"<>Sat",$D$1:$AH$1,"<>Mon"),"") -> 11.833333
A28: Sant9938 | B28: Hiren Patel | D28: 10.416667 | E28: 11 | F28: 3.75 | H28: 6.9166667 | I28: 10.416667 | J28: 8.6666667 | K28: 9.8333333 | L28: 10.083333 | M28: 6.5 | P28: 10.416667 | Q28: 10.416667 | R28: 10.666667 | S28: 9.6666667 | T28: 4.8333333 | V28: 4.9166667 | W28: 9.75 | Y28: 10.333333 | Z28: 8.75 | AA28: 3.5 | AC28: 5.8333333 | AD28: 8.5 | AE28: 9 | AI28: =IFERROR(AVERAGEIFS(D28:AH28,$D$1:$AH$1,"<>Sun",$D$1:$AH$1,"<>Sat",$D$1:$AH$1,"<>Mon"),"") -> 9.8611111
A29: Shaj10695 | B29: Hiren Patel | D29: 13.083333 | E29: 12.5 | H29: 8.1666667 | I29: 12 | J29: 12.083333 | K29: 13.5 | L29: 12 | M29: 11.333333 | N29: 4.4166667 | O29: 7.5833333 | P29: 13.833333 | Q29: 12.916667 | R29: 12.083333 | S29: 13.666667 | T29: 6.75 | U29: 3.8333333 | V29: 9.75 | W29: 13.75 | X29: 12.833333 | Y29: 12.916667 | Z29: 12.833333 | AB29: 3.6666667 | AC29: 12.083333 | AD29: 13.166667 | AE29: 12.583333 | AI29: =IFERROR(AVERAGEIFS(D29:AH29,$D$1:$AH$1,"<>Sun",$D$1:$AH$1,"<>Sat",$D$1:$AH$1,"<>Mon"),"") -> 12.859375
A30: Shee10038 | B30: Hiren Patel | D30: 8.3333333 | F30: 3.6666667 | H30: 5.4166667 | I30: 8.5833333 | J30: 9.6666667 | K30: 9.0833333 | L30: 9.1666667 | M30: 8 | O30: 8.3333333 | P30: 9 | Q30: 9.75 | R30: 9 | S30: 9.1666667 | T30: 4.25 | V30: 5.25 | W30: 8.1666667 | X30: 9.6666667 | Y30: 7.9166667 | AC30: 6.5833333 | AD30: 8.5 | AE30: 9.5 | AI30: =IFERROR(AVERAGEIFS(D30:AH30,$D$1:$AH$1,"<>Sun",$D$1:$AH$1,"<>Sat",$D$1:$AH$1,"<>Mon"),"") -> 8.9642857
A31: BOIC005 | B31: Hiren Patel | D31: 8.5833333 | E31: 9.6666667 | F31: 3.3333333 | G31: 6 | H31: 5.3333333 | I31: 8.8333333 | J31: 8.0833333 | K31: 10 | L31: 8.5 | M31: 7.3333333 | N31: 5.1666667 | O31: 6.9166667 | P31: 10.083333 | Q31: 11.5 | R31: 11.583333 | S31: 8.9166667 | T31: 2.8333333 | U31: 0.33333333 | V31: 6.3333333 | W31: 9.5 | X31: 8.6666667 | Y31: 4.3333333 | Z31: 8.25 | AA31: 3.1666667 | AB31: 4.25 | AC31: 5.3333333 | AD31: 8.75 | AE31: 7.0833333 | AI31: =IFERROR(AVERAGEIFS(D31:AH31,$D$1:$AH$1,"<>Sun",$D$1:$AH$1,"<>Sat",$D$1:$AH$1,"<>Mon"),"") -> 8.8958333
A32: Shya10534 | B32: Hiren Patel | D32: 5.9166667 | E32: 5.5 | F32: 4.8333333 | H32: 4.6666667 | I32: 5 | J32: 5.25 | K32: 4.8333333 | L32: 4.75 | M32: 4.6666667 | O32: 5.0833333 | P32: 5.75 | Q32: 5.4166667 | R32: 6.25 | S32: 5.5 | T32: 4.75 | V32: 5.5833333 | W32: 5.9166667 | X32: 5.25 | Y32: 6.4166667 | AC32: 5.8333333 | AD32: 6.9166667 | AE32: 5.25 | AI32: =IFERROR(AVERAGEIFS(D32:AH32,$D$1:$AH$1,"<>Sun",$D$1:$AH$1,"<>Sat",$D$1:$AH$1,"<>Mon"),"") -> 5.5944444
A33: simi11060 | B33: Hiren Patel | D33: 5.5833333 | E33: 5.8333333 | F33: 1.75 | H33: 2.5 | I33: 5.0833333 | J33: 5.3333333 | K33: 5.4166667 | L33: 5.9166667 | M33: 5.25 | O33: 4.6666667 | P33: 5.75 | Q33: 5.9166667 | R33: 5.9166667 | S33: 6.3333333 | T33: 1.1666667 | V33: 2.8333333 | W33: 5 | X33: 5.4166667 | Y33: 5.5 | Z33: 5.6666667 | AA33: 1.1666667 | AC33: 2.75 | AD33: 6.3333333 | AE33: 5.8333333 | AI33: =IFERROR(AVERAGEIFS(D33:AH33,$D$1:$AH$1,"<>Sun",$D$1:$AH$1,"<>Sat",$D$1:$AH$1,"<>Mon"),"") -> 5.6770833
A34: Simi11008 | B34: Hiren Patel | D34: 8.9166667 | E34: 8.9166667 | F34: 3.4166667 | H34: 4.6666667 | I34: 9.0833333 | J34: 9.8333333 | K34: 9.5 | L34: 8.8333333 | M34: 8.5 | O34: 5.8333333 | P34: 10.5 | Q34: 9 | R34: 10.666667 | S34: 10.166667 | T34: 5.1666667 | V34: 5.8333333 | W34: 10.5 | X34: 6 | Y34: 8.9166667 | Z34: 8.4166667 | AA34: 4.5 | AC34: 4.8333333 | AD34: 1 | AE34: 9.0833333 | AI34: =IFERROR(AVERAGEIFS(D34:AH34,$D$1:$AH$1,"<>Sun",$D$1:$AH$1,"<>Sat",$D$1:$AH$1,"<>Mon"),"") -> 8.7083333
A35: Sowm9753 | B35: Hiren Patel | D35: 6.4166667 | E35: 6.9166667 | F35: 3.0833333 | I35: 8.4166667 | J35: 7.5 | K35: 7.6666667 | L35: 6.5 | M35: 6.0833333 | P35: 8.1666667 | Q35: 7.0833333 | R35: 8.4166667 | S35: 8.3333333 | T35: 2.9166667 | V35: 3.75 | W35: 5.25 | X35: 6.9166667 | Y35: 6.5833333 | Z35: 6.75 | AA35: 4 | AB35: 2.0833333 | AC35: 4.6666667 | AD35: 6.8333333 | AE35: 6.75 | AI35: =IFERROR(AVERAGEIFS(D35:AH35,$D$1:$AH$1,"<>Sun",$D$1:$AH$1,"<>Sat",$D$1:$AH$1,"<>Mon"),"") -> 7.15625
A36: Srid11033 | B36: Hiren Patel | D36: 7.5 | E36: 6.25 | F36: 2.4166667 | J36: 6.9166667 | K36: 7.1666667 | L36: 7.25 | M36: 6.1666667 | O36: 3.75 | P36: 6.75 | Q36: 7.1666667 | R36: 6.9166667 | S36: 7.0833333 | T36: 3.25 | V36: 3.5 | W36: 7.9166667 | X36: 7.0833333 | Y36: 7.0833333 | Z36: 6.0833333 | AA36: 5.1666667 | AC36: 3.6666667 | AD36: 7.6666667 | AE36: 7.4166667 | AI36: =IFERROR(AVERAGEIFS(D36:AH36,$D$1:$AH$1,"<>Sun",$D$1:$AH$1,"<>Sat",$D$1:$AH$1,"<>Mon"),"") -> 7.0833333
A37: Suge10290 | B37: Hiren Patel | D37: 4.9166667 | E37: 4 | H37: 3.6666667 | I37: 4.75 | J37: 5.3333333 | K37: 4.8333333 | L37: 5.1666667 | O37: 2.9166667 | P37: 5.1666667 | Q37: 5.5833333 | R37: 5.3333333 | T37: 2.75 | W37: 4.75 | X37: 6.0833333 | Y37: 5 | Z37: 5.25 | AA37: 2.5 | AC37: 3 | AD37: 4.9166667 | AE37: 4.9166667 | AI37: =IFERROR(AVERAGEIFS(D37:AH37,$D$1:$AH$1,"<>Sun",$D$1:$AH$1,"<>Sat",$D$1:$AH$1,"<>Mon"),"") -> 5.0666667
A38: Sure10542 | B38: Hiren Patel | D38: 7 | E38: 6.5833333 | H38: 3.75 | I38: 7.1666667 | J38: 6.5833333 | K38: 6.5833333 | M38: 6.0833333 | O38: 3.75 | P38: 7 | Q38: 6.75 | R38: 6.5833333 | S38: 5.9166667 | T38: 3.75 | V38: 4.8333333 | W38: 6.75 | X38: 6 | Y38: 6.6666667 | Z38: 7.5833333 | AA38: 2.1666667 | AC38: 6.4166667 | AD38: 7.9166667 | AE38: 8.1666667 | AI38: =IFERROR(AVERAGEIFS(D38:AH38,$D$1:$AH$1,"<>Sun",$D$1:$AH$1,"<>Sat",$D$1:$AH$1,"<>Mon"),"") -> 6.8833333
A39: Thaj9574 | B39: Hiren Patel | D39: 7.6666667 | E39: 7.75 | F39: 4.0833333 | H39: 6.0833333 | I39: 8.5833333 | J39: 8.25 | K39: 8.3333333 | L39: 7.6666667 | M39: 7.75 | O39: 6 | P39: 8.5 | Q39: 8.0833333 | R39: 8.1666667 | S39: 9.5 | T39: 6.25 | V39: 5.3333333 | W39: 7.8333333 | X39: 9.0833333 | Y39: 8.75 | Z39: 8.75 | AC39: 6 | AD39: 8.5 | AE39: 8.8333333 | AI39: =IFERROR(AVERAGEIFS(D39:AH39,$D$1:$AH$1,"<>Sun",$D$1:$AH$1,"<>Sat",$D$1:$AH$1,"<>Mon"),"") -> 8.390625
A40: Vani10406 | B40: Hiren Patel | D40: 11.333333 | E40: 10.916667 | F40: 4.8333333 | H40: 8.5 | I40: 12.416667 | J40: 9.5 | L40: 10.833333 | M40: 7 | O40: 7.9166667 | P40: 11.75 | Q40: 13.083333 | R40: 11.75 | S40: 12 | T40: 5.1666667 | V40: 7.5 | W40: 11.75 | X40: 12.916667 | Z40: 12.25 | AA40: 3.0833333 | AC40: 5.4166667 | AD40: 11.583333 | AE40: 7.0833333 | AI40: =IFERROR(AVERAGEIFS(D40:AH40,$D$1:$AH$1,"<>Sun",$D$1:$AH$1,"<>Sat",$D$1:$AH$1,"<>Mon"),"") -> 11.369048
...

Sheet UK Holiday

Sheet DUP Summary
B1: Define No Of Days in Month -> | C1: 20 | H1: =TEXT(H2,"ddd") -> Thu | K1: =TEXT(K2,"ddd") -> Fri | N1: =TEXT(N2,"ddd") -> Sat | Q1: =TEXT(Q2,"ddd") -> Sun | T1: =TEXT(T2,"ddd") -> Mon | W1: =TEXT(W2,"ddd") -> Tue | Z1: =TEXT(Z2,"ddd") -> Wed | AC1: =TEXT(AC2,"ddd") -> Thu | AF1: =TEXT(AF2,"ddd") -> Fri | AI1: =TEXT(AI2,"ddd") -> Sat | AL1: =TEXT(AL2,"ddd") -> Sun | AO1: =TEXT(AO2,"ddd") -> Mon | AR1: =TEXT(AR2,"ddd") -> Tue | AU1: =TEXT(AU2,"ddd") -> Wed | AX1: =TEXT(AX2,"ddd") -> Thu | BA1: =TEXT(BA2,"ddd") -> Fri | BD1: =TEXT(BD2,"ddd") -> Sat | BG1: =TEXT(BG2,"ddd") -> Sun | BJ1: =TEXT(BJ2,"ddd") -> Mon | BM1: =TEXT(BM2,"ddd") -> Tue | BP1: =TEXT(BP2,"ddd") -> Wed | BS1: =TEXT(BS2,"ddd") -> Thu | BV1: =TEXT(BV2,"ddd") -> Fri | BY1: =TEXT(BY2,"ddd") -> Sat | CB1: =TEXT(CB2,"ddd") -> Sun | CE1: =TEXT(CE2,"ddd") -> Mon | CH1: =TEXT(CH2,"ddd") -> Tue | CK1: =TEXT(CK2,"ddd") -> Wed | CN1: =TEXT(CN2,"ddd") -> Thu | CQ1: =TEXT(CQ2,"ddd") -> Fri | CT1: =TEXT(CT2,"ddd") -> Sat | DB1: No of Day's Woked | DC1: Remaining Days
H2: 46079 | I2: =H2 -> 46079 | J2: =H2 -> 46079 | K2: =H2+1 -> 46080 | L2: =K2 -> 46080 | M2: =K2 -> 46080 | N2: =K2+1 -> 46081 | O2: =N2 -> 46081 | P2: =N2 -> 46081 | Q2: =N2+1 -> 46082 | R2: =Q2 -> 46082 | S2: =Q2 -> 46082 | T2: =Q2+1 -> 46083 | U2: =T2 -> 46083 | V2: =T2 -> 46083 | W2: =T2+1 -> 46084 | X2: =W2 -> 46084 | Y2: =W2 -> 46084 | Z2: =W2+1 -> 46085 | AA2: =Z2 -> 46085 | AB2: =Z2 -> 46085 | AC2: =Z2+1 -> 46086 | AD2: =AC2 -> 46086 | AE2: =AC2 -> 46086 | AF2: =AC2+1 -> 46087 | AG2: =AF2 -> 46087 | AH2: =AF2 -> 46087 | AI2: =AF2+1 -> 46088 | AJ2: =AI2 -> 46088 | AK2: =AI2 -> 46088 | AL2: =AI2+1 -> 46089 | AM2: =AL2 -> 46089 | AN2: =AL2 -> 46089 | AO2: =AL2+1 -> 46090 | AP2: =AO2 -> 46090 | AQ2: =AO2 -> 46090 | AR2: =AO2+1 -> 46091 | AS2: =AR2 -> 46091 | AT2: =AR2 -> 46091 | AU2: =AR2+1 -> 46092 | AV2: =AU2 -> 46092 | AW2: =AU2 -> 46092 | AX2: =AU2+1 -> 46093 | AY2: =AX2 -> 46093 | AZ2: =AX2 -> 46093 | BA2: =AX2+1 -> 46094 | BB2: =BA2 -> 46094 | BC2: =BA2 -> 46094 | BD2: =BA2+1 -> 46095 | BE2: =BD2 -> 46095 | BF2: =BD2 -> 46095 | BG2: =BD2+1 -> 46096 | BH2: =BG2 -> 46096 | BI2: =BG2 -> 46096 | BJ2: =BG2+1 -> 46097 | BK2: =BJ2 -> 46097 | BL2: =BJ2 -> 46097 | BM2: =BJ2+1 -> 46098 | BN2: =BM2 -> 46098 | BO2: =BM2 -> 46098 | BP2: =BM2+1 -> 46099 | BQ2: =BP2 -> 46099 | BR2: =BP2 -> 46099 | BS2: =BP2+1 -> 46100 | BT2: =BS2 -> 46100 | BU2: =BS2 -> 46100 | BV2: =BS2+1 -> 46101 | BW2: =BV2 -> 46101 | BX2: =BV2 -> 46101 | BY2: =BV2+1 -> 46102 | BZ2: =BY2 -> 46102 | CA2: =BY2 -> 46102 | CB2: =BY2+1 -> 46103 | CC2: =CB2 -> 46103 | CD2: =CB2 -> 46103 | CE2: =CB2+1 -> 46104 | CF2: =CE2 -> 46104 | CG2: =CE2 -> 46104 | CH2: =CE2+1 -> 46105 | CI2: =CH2 -> 46105 | CJ2: =CH2 -> 46105 | CK2: =CH2+1 -> 46106 | CL2: =CK2 -> 46106 | CM2: =CK2 -> 46106 | CN2: =CK2+1 -> 46107 | CO2: =CN2 -> 46107 | CP2: =CN2 -> 46107 | CQ2: =CN2+1 -> 46108 | CR2: =CQ2 -> 46108 | CS2: =CQ2 -> 46108 | CT2: =CQ2+1 -> 46109 | CU2: =CT2 -> 46109 | CV2: =CT2 -> 46109 | DB2: =SUM('Productivity Dump'!$E$1:$AI$1) -> 22.5 | DC2: =C1-DB2 -> -2.5 | DF2: Overall
A3: EC | B3: Name | C3: DIT ID | D3: TL | E3: Monthly Target | F3: Daily Target | G3: Target For Weekends (50%) | H3: Productivity | I3: Attendance | J3: Active Hours | K3: Productivity | L3: Attendance | M3: Active Hours | N3: Productivity | O3: Attendance | P3: Active Hours | Q3: Productivity | R3: Attendance | S3: Active Hours | T3: Productivity | U3: Attendance | V3: Active Hours | W3: Productivity | X3: Attendance | Y3: Active Hours | Z3: Productivity | AA3: Attendance | AB3: Active Hours | AC3: Productivity | AD3: Attendance | AE3: Active Hours | AF3: Productivity | AG3: Attendance | AH3: Active Hours | AI3: Productivity | AJ3: Attendance | AK3: Active Hours | AL3: Productivity | AM3: Attendance | AN3: Active Hours | AO3: Productivity | AP3: Attendance | AQ3: Active Hours | AR3: Productivity | AS3: Attendance | AT3: Active Hours | AU3: Productivity | AV3: Attendance | AW3: Active Hours | AX3: Productivity | AY3: Attendance | AZ3: Active Hours | BA3: Productivity | BB3: Attendance | BC3: Active Hours | BD3: Productivity | BE3: Attendance | BF3: Active Hours | BG3: Productivity | BH3: Attendance | BI3: Active Hours | BJ3: Productivity | BK3: Attendance | BL3: Active Hours | BM3: Productivity | BN3: Attendance | BO3: Active Hours | BP3: Productivity | BQ3: Attendance | BR3: Active Hours | BS3: Productivity | BT3: Attendance | BU3: Active Hours | BV3: Productivity | BW3: Attendance | BX3: Active Hours | BY3: Productivity | BZ3: Attendance | CA3: Active Hours | CB3: Productivity | CC3: Attendance | CD3: Active Hours | CE3: Productivity | CF3: Attendance | CG3: Active Hours | CH3: Productivity | CI3: Attendance | CJ3: Active Hours | CK3: Productivity | CL3: Attendance | CM3: Active Hours | CN3: Productivity | CO3: Attendance | CP3: Active Hours | CQ3: Productivity | CR3: Attendance | CS3: Active Hours | CT3: Productivity | CU3: Attendance | CV3: Active Hours | DA3: Total Active Hour's Worked | DB3: Monthly Achieved Overall Lines | DC3: Yet to Achieve | DD3: Yet to Achieve Per Day | DF3: If productivity is Zero and Attendance is P | DG3: If productivity is <50% and attendance is P | DH3: If productivity is >50% to <80% and attendance is P | DI3: If productivity is >80% to <100 % and attendance is P
A4: BOI8268 | B4: Bhaskar .S | C4: Bhas8268 | D4: Hiren Patel | E4: 22555.556 | F4: =E4/$C$1 -> 1127.7778 | G4: =F4*0.5 -> 563.88889 | H4: =_xlfn.IFNA(IF(H$3="Productivity", INDEX('Productivity Dump'!$E$4:$AJ$500, MATCH($A4,'Productivity Dump'!$A$4:$A$500,0), MATCH(H$2,'Productivity Dump'!$E$3:$AJ$3,0) ), IF(H$3="Attendance", INDEX('Attendance Dump'!$E$2:$AI$400, MATCH($A4,'Attendance Dump'!$B$2:$B$400,0), MATCH(H$2,'Attendance Dump'!$E$1:$AI$1,0) ), INDEX('Active Hour''s Dump'!$D$3:$AH$337, MATCH($C4,'Active Hour''s Dump'!$A$3:$A$337,0), MATCH(H$2,'Active Hour''s Dump'!$D$2:$AH$2,0) ))),"") -> 1182.617 | I4: =_xlfn.IFNA(IF(I$3="Productivity", INDEX('Productivity Dump'!$E$4:$AJ$500, MATCH($A4,'Productivity Dump'!$A$4:$A$500,0), MATCH(I$2,'Productivity Dump'!$E$3:$AJ$3,0) ), IF(I$3="Attendance", INDEX('Attendance Dump'!$E$2:$AI$400, MATCH($A4,'Attendance Dump'!$B$2:$B$400,0), MATCH(I$2,'Attendance Dump'!$E$1:$AI$1,0) ), INDEX('Active Hour''s Dump'!$D$3:$AH$337, MATCH($C4,'Active Hour''s Dump'!$A$3:$A$337,0), MATCH(I$2,'Active Hour''s Dump'!$D$2:$AH$2,0) ))),"") -> P | J4: =_xlfn.IFNA(IF(J$3="Productivity", INDEX('Productivity Dump'!$E$4:$AJ$500, MATCH($A4,'Productivity Dump'!$A$4:$A$500,0), MATCH(J$2,'Productivity Dump'!$E$3:$AJ$3,0) ), IF(J$3="Attendance", INDEX('Attendance Dump'!$E$2:$AI$400, MATCH($A4,'Attendance Dump'!$B$2:$B$400,0), MATCH(J$2,'Attendance Dump'!$E$1:$AI$1,0) ), INDEX('Active Hour''s Dump'!$D$3:$AH$337, MATCH($C4,'Active Hour''s Dump'!$A$3:$A$337,0), MATCH(J$2,'Active Hour''s Dump'!$D$2:$AH$2,0) ))),"") -> 10.75 | K4: =_xlfn.IFNA(IF(K$3="Productivity", INDEX('Productivity Dump'!$E$4:$AJ$500, MATCH($A4,'Productivity Dump'!$A$4:$A$500,0), MATCH(K$2,'Productivity Dump'!$E$3:$AJ$3,0) ), IF(K$3="Attendance", INDEX('Attendance Dump'!$E$2:$AI$400, MATCH($A4,'Attendance Dump'!$B$2:$B$400,0), MATCH(K$2,'Attendance Dump'!$E$1:$AI$1,0) ), INDEX('Active Hour''s Dump'!$D$3:$AH$337, MATCH($C4,'Active Hour''s Dump'!$A$3:$A$337,0), MATCH(K$2,'Active Hour''s Dump'!$D$2:$AH$2,0) ))),"") -> 921.598 | L4: =_xlfn.IFNA(IF(L$3="Productivity", INDEX('Productivity Dump'!$E$4:$AJ$500, MATCH($A4,'Productivity Dump'!$A$4:$A$500,0), MATCH(L$2,'Productivity Dump'!$E$3:$AJ$3,0) ), IF(L$3="Attendance", INDEX('Attendance Dump'!$E$2:$AI$400, MATCH($A4,'Attendance Dump'!$B$2:$B$400,0), MATCH(L$2,'Attendance Dump'!$E$1:$AI$1,0) ), INDEX('Active Hour''s Dump'!$D$3:$AH$337, MATCH($C4,'Active Hour''s Dump'!$A$3:$A$337,0), MATCH(L$2,'Active Hour''s Dump'!$D$2:$AH$2,0) ))),"") -> P | M4: =_xlfn.IFNA(IF(M$3="Productivity", INDEX('Productivity Dump'!$E$4:$AJ$500, MATCH($A4,'Productivity Dump'!$A$4:$A$500,0), MATCH(M$2,'Productivity Dump'!$E$3:$AJ$3,0) ), IF(M$3="Attendance", INDEX('Attendance Dump'!$E$2:$AI$400, MATCH($A4,'Attendance Dump'!$B$2:$B$400,0), MATCH(M$2,'Attendance Dump'!$E$1:$AI$1,0) ), INDEX('Active Hour''s Dump'!$D$3:$AH$337, MATCH($C4,'Active Hour''s Dump'!$A$3:$A$337,0), MATCH(M$2,'Active Hour''s Dump'!$D$2:$AH$2,0) ))),"") -> 10.25 | N4: =_xlfn.IFNA(IF(N$3="Productivity", INDEX('Productivity Dump'!$E$4:$AJ$500, MATCH($A4,'Productivity Dump'!$A$4:$A$500,0), MATCH(N$2,'Productivity Dump'!$E$3:$AJ$3,0) ), IF(N$3="Attendance", INDEX('Attendance Dump'!$E$2:$AI$400, MATCH($A4,'Attendance Dump'!$B$2:$B$400,0), MATCH(N$2,'Attendance Dump'!$E$1:$AI$1,0) ), INDEX('Active Hour''s Dump'!$D$3:$AH$337, MATCH($C4,'Active Hour''s Dump'!$A$3:$A$337,0), MATCH(N$2,'Active Hour''s Dump'!$D$2:$AH$2,0) ))),"") -> 646.92 | O4: =_xlfn.IFNA(IF(O$3="Productivity", INDEX('Productivity Dump'!$E$4:$AJ$500, MATCH($A4,'Productivity Dump'!$A$4:$A$500,0), MATCH(O$2,'Productivity Dump'!$E$3:$AJ$3,0) ), IF(O$3="Attendance", INDEX('Attendance Dump'!$E$2:$AI$400, MATCH($A4,'Attendance Dump'!$B$2:$B$400,0), MATCH(O$2,'Attendance Dump'!$E$1:$AI$1,0) ), INDEX('Active Hour''s Dump'!$D$3:$AH$337, MATCH($C4,'Active Hour''s Dump'!$A$3:$A$337,0), MATCH(O$2,'Active Hour''s Dump'!$D$2:$AH$2,0) ))),"") -> P | ... CV4: =_xlfn.IFNA(IF(CV$3="Productivity", INDEX('Productivity Dump'!$E$4:$AJ$500, MATCH($A4,'Productivity Dump'!$A$4:$A$500,0), MATCH(CV$2,'Productivity Dump'!$E$3:$AJ$3,0) ), IF(CV$3="Attendance", INDEX('Attendance Dump'!$E$2:$AI$400, MATCH($A4,'Attendance Dump'!$B$2:$B$400,0), MATCH(CV$2,'Attendance Dump'!$E$1:$AI$1,0) ), INDEX('Active Hour''s Dump'!$D$3:$AH$337, MATCH($C4,'Active Hour''s Dump'!$A$3:$A$337,0), MATCH(CV$2,'Active Hour''s Dump'!$D$2:$AH$2,0) ))),"") -> 0 | DA4: =SUMIFS($H4:$CY4,$H$3:$CY$3,"Active Hours") -> 235.66667 | DB4: =SUMIFS($H4:$CY4,$H$3:$CY$3,"Productivity") -> 22589.013 | DC4: =MAX(0,E4-DB4) -> 0 | DD4: =IFERROR(MAX(0,DC4/$DC$2),DC4) -> 0 | DF4: {=SUMPRODUCT( (MOD(COLUMN(H4:CV4) - COLUMN(H4), 3) = 0) * (H4:CV4 = 0) * (I4:CW4 = "P") * (COUNTIF(UKHoliday, H$2:CV$2) = 0) )} -> 0 | DG4: {=SUMPRODUCT( (MOD(COLUMN(H4:CV4) - COLUMN(H4), 3) = 0) * (H4:CV4 > 0) * (H4:CV4 < 0.5 * IF(((WEEKDAY(H$2:CV$2, 2) = 1) + (WEEKDAY(H$2:CV$2, 2) = 6)), G4, F4)) * (I4:CW4 = "P") * (COUNTIF(UKHoliday, H$2:CV$2) = 0) )} -> 0 | DH4: {=SUMPRODUCT( (MOD(COLUMN(H4:CV4) - COLUMN(H4), 3) = 0) * (H4:CV4 > 0.5 * IF(((WEEKDAY(H$2:CV$2, 2) = 1) + (WEEKDAY(H$2:CV$2, 2) = 6)), $G4, $F4)) * (H4:CV4 < 0.8 * IF(((WEEKDAY(H$2:CV$2, 2) = 1) + (WEEKDAY(H$2:CV$2, 2) = 6)), $G4, $F4)) * (I4:CW4 = "P") * (COUNTIF(UKHoliday, H$2:CV$2) = 0) )} -> 5 | DI4: {=SUMPRODUCT( (MOD(COLUMN(H4:CV4) - COLUMN(H4), 3) = 0) * (H4:CV4 > 0.8 * IF(((WEEKDAY(H$2:CV$2, 2) = 1) + (WEEKDAY(H$2:CV$2, 2) = 6)), $G4, $F4)) * (H4:CV4 < 1 * IF(((WEEKDAY(H$2:CV$2, 2) = 1) + (WEEKDAY(H$2:CV$2, 2) = 6)), $G4, $F4)) * (I4:CW4 = "P") * (COUNTIF(UKHoliday, H$2:CV$2) = 0) )} -> 10
A5: BOI8269 | B5: Poornima Marappa | C5: Poor8269 | D5: Hiren Patel | E5: 24000 | F5: =E5/$C$1 -> 1200 | G5: =F5*0.5 -> 600 | H5: =_xlfn.IFNA(IF(H$3="Productivity", INDEX('Productivity Dump'!$E$4:$AJ$500, MATCH($A5,'Productivity Dump'!$A$4:$A$500,0), MATCH(H$2,'Productivity Dump'!$E$3:$AJ$3,0) ), IF(H$3="Attendance", INDEX('Attendance Dump'!$E$2:$AI$400, MATCH($A5,'Attendance Dump'!$B$2:$B$400,0), MATCH(H$2,'Attendance Dump'!$E$1:$AI$1,0) ), INDEX('Active Hour''s Dump'!$D$3:$AH$337, MATCH($C5,'Active Hour''s Dump'!$A$3:$A$337,0), MATCH(H$2,'Active Hour''s Dump'!$D$2:$AH$2,0) ))),"") -> 1117.703 | I5: =_xlfn.IFNA(IF(I$3="Productivity", INDEX('Productivity Dump'!$E$4:$AJ$500, MATCH($A5,'Productivity Dump'!$A$4:$A$500,0), MATCH(I$2,'Productivity Dump'!$E$3:$AJ$3,0) ), IF(I$3="Attendance", INDEX('Attendance Dump'!$E$2:$AI$400, MATCH($A5,'Attendance Dump'!$B$2:$B$400,0), MATCH(I$2,'Attendance Dump'!$E$1:$AI$1,0) ), INDEX('Active Hour''s Dump'!$D$3:$AH$337, MATCH($C5,'Active Hour''s Dump'!$A$3:$A$337,0), MATCH(I$2,'Active Hour''s Dump'!$D$2:$AH$2,0) ))),"") -> P | J5: =_xlfn.IFNA(IF(J$3="Productivity", INDEX('Productivity Dump'!$E$4:$AJ$500, MATCH($A5,'Productivity Dump'!$A$4:$A$500,0), MATCH(J$2,'Productivity Dump'!$E$3:$AJ$3,0) ), IF(J$3="Attendance", INDEX('Attendance Dump'!$E$2:$AI$400, MATCH($A5,'Attendance Dump'!$B$2:$B$400,0), MATCH(J$2,'Attendance Dump'!$E$1:$AI$1,0) ), INDEX('Active Hour''s Dump'!$D$3:$AH$337, MATCH($C5,'Active Hour''s Dump'!$A$3:$A$337,0), MATCH(J$2,'Active Hour''s Dump'!$D$2:$AH$2,0) ))),"") -> 5.6666667 | K5: =_xlfn.IFNA(IF(K$3="Productivity", INDEX('Productivity Dump'!$E$4:$AJ$500, MATCH($A5,'Productivity Dump'!$A$4:$A$500,0), MATCH(K$2,'Productivity Dump'!$E$3:$AJ$3,0) ), IF(K$3="Attendance", INDEX('Attendance Dump'!$E$2:$AI$400, MATCH($A5,'Attendance Dump'!$B$2:$B$400,0), MATCH(K$2,'Attendance Dump'!$E$1:$AI$1,0) ), INDEX('Active Hour''s Dump'!$D$3:$AH$337, MATCH($C5,'Active Hour''s Dump'!$A$3:$A$337,0), MATCH(K$2,'Active Hour''s Dump'!$D$2:$AH$2,0) ))),"") -> 1134.393 | L5: =_xlfn.IFNA(IF(L$3="Productivity", INDEX('Productivity Dump'!$E$4:$AJ$500, MATCH($A5,'Productivity Dump'!$A$4:$A$500,0), MATCH(L$2,'Productivity Dump'!$E$3:$AJ$3,0) ), IF(L$3="Attendance", INDEX('Attendance Dump'!$E$2:$AI$400, MATCH($A5,'Attendance Dump'!$B$2:$B$400,0), MATCH(L$2,'Attendance Dump'!$E$1:$AI$1,0) ), INDEX('Active Hour''s Dump'!$D$3:$AH$337, MATCH($C5,'Active Hour''s Dump'!$A$3:$A$337,0), MATCH(L$2,'Active Hour''s Dump'!$D$2:$AH$2,0) ))),"") -> P | M5: =_xlfn.IFNA(IF(M$3="Productivity", INDEX('Productivity Dump'!$E$4:$AJ$500, MATCH($A5,'Productivity Dump'!$A$4:$A$500,0), MATCH(M$2,'Productivity Dump'!$E$3:$AJ$3,0) ), IF(M$3="Attendance", INDEX('Attendance Dump'!$E$2:$AI$400, MATCH($A5,'Attendance Dump'!$B$2:$B$400,0), MATCH(M$2,'Attendance Dump'!$E$1:$AI$1,0) ), INDEX('Active Hour''s Dump'!$D$3:$AH$337, MATCH($C5,'Active Hour''s Dump'!$A$3:$A$337,0), MATCH(M$2,'Active Hour''s Dump'!$D$2:$AH$2,0) ))),"") -> 6 | N5: =_xlfn.IFNA(IF(N$3="Productivity", INDEX('Productivity Dump'!$E$4:$AJ$500, MATCH($A5,'Productivity Dump'!$A$4:$A$500,0), MATCH(N$2,'Productivity Dump'!$E$3:$AJ$3,0) ), IF(N$3="Attendance", INDEX('Attendance Dump'!$E$2:$AI$400, MATCH($A5,'Attendance Dump'!$B$2:$B$400,0), MATCH(N$2,'Attendance Dump'!$E$1:$AI$1,0) ), INDEX('Active Hour''s Dump'!$D$3:$AH$337, MATCH($C5,'Active Hour''s Dump'!$A$3:$A$337,0), MATCH(N$2,'Active Hour''s Dump'!$D$2:$AH$2,0) ))),"") -> 705.748 | O5: =_xlfn.IFNA(IF(O$3="Productivity", INDEX('Productivity Dump'!$E$4:$AJ$500, MATCH($A5,'Productivity Dump'!$A$4:$A$500,0), MATCH(O$2,'Productivity Dump'!$E$3:$AJ$3,0) ), IF(O$3="Attendance", INDEX('Attendance Dump'!$E$2:$AI$400, MATCH($A5,'Attendance Dump'!$B$2:$B$400,0), MATCH(O$2,'Attendance Dump'!$E$1:$AI$1,0) ), INDEX('Active Hour''s Dump'!$D$3:$AH$337, MATCH($C5,'Active Hour''s Dump'!$A$3:$A$337,0), MATCH(O$2,'Active Hour''s Dump'!$D$2:$AH$2,0) ))),"") -> P | ... CV5: =_xlfn.IFNA(IF(CV$3="Productivity", INDEX('Productivity Dump'!$E$4:$AJ$500, MATCH($A5,'Productivity Dump'!$A$4:$A$500,0), MATCH(CV$2,'Productivity Dump'!$E$3:$AJ$3,0) ), IF(CV$3="Attendance", INDEX('Attendance Dump'!$E$2:$AI$400, MATCH($A5,'Attendance Dump'!$B$2:$B$400,0), MATCH(CV$2,'Attendance Dump'!$E$1:$AI$1,0) ), INDEX('Active Hour''s Dump'!$D$3:$AH$337, MATCH($C5,'Active Hour''s Dump'!$A$3:$A$337,0), MATCH(CV$2,'Active Hour''s Dump'!$D$2:$AH$2,0) ))),"") -> 0 | DA5: =SUMIFS($H5:$CY5,$H$3:$CY$3,"Active Hours") -> 114.08333 | DB5: =SUMIFS($H5:$CY5,$H$3:$CY$3,"Productivity") -> 20826.782 | DC5: =MAX(0,E5-DB5) -> 3173.218 | DD5: =IFERROR(MAX(0,DC5/$DC$2),DC5) -> 0 | DF5: {=SUMPRODUCT( (MOD(COLUMN(H5:CV5) - COLUMN(H5), 3) = 0) * (H5:CV5 = 0) * (I5:CW5 = "P") * (COUNTIF(UKHoliday, H$2:CV$2) = 0) )} -> 0 | DG5: {=SUMPRODUCT( (MOD(COLUMN(H5:CV5) - COLUMN(H5), 3) = 0) * (H5:CV5 > 0) * (H5:CV5 < 0.5 * IF(((WEEKDAY(H$2:CV$2, 2) = 1) + (WEEKDAY(H$2:CV$2, 2) = 6)), G5, F5)) * (I5:CW5 = "P") * (COUNTIF(UKHoliday, H$2:CV$2) = 0) )} -> 0 | DH5: {=SUMPRODUCT( (MOD(COLUMN(H5:CV5) - COLUMN(H5), 3) = 0) * (H5:CV5 > 0.5 * IF(((WEEKDAY(H$2:CV$2, 2) = 1) + (WEEKDAY(H$2:CV$2, 2) = 6)), $G5, $F5)) * (H5:CV5 < 0.8 * IF(((WEEKDAY(H$2:CV$2, 2) = 1) + (WEEKDAY(H$2:CV$2, 2) = 6)), $G5, $F5)) * (I5:CW5 = "P") * (COUNTIF(UKHoliday, H$2:CV$2) = 0) )} -> 3 | DI5: {=SUMPRODUCT( (MOD(COLUMN(H5:CV5) - COLUMN(H5), 3) = 0) * (H5:CV5 > 0.8 * IF(((WEEKDAY(H$2:CV$2, 2) = 1) + (WEEKDAY(H$2:CV$2, 2) = 6)), $G5, $F5)) * (H5:CV5 < 1 * IF(((WEEKDAY(H$2:CV$2, 2) = 1) + (WEEKDAY(H$2:CV$2, 2) = 6)), $G5, $F5)) * (I5:CW5 = "P") * (COUNTIF(UKHoliday, H$2:CV$2) = 0) )} -> 14
